Workbook

Sheet Instructions
A1: Deviation and CAPA Tracker
A2: QA-DEV-006 · Simulated data for a portfolio demonstration. No real site data.
A4: What this is | B4: An Excel deviation and CAPA tracker. Every status, age, repeat flag, CAPA effectiveness result and dashboard number is a formula, so it updates when you add records, close them, or change the data date.
A6: SHEETS
A7: Settings | B7: Data date, closure target and the other rules. Change these and the whole workbook follows. Also holds the drop-down lists.
A8: Deviation Log | B8: One row per deviation. Enter data in the blue-text columns A to J; columns K to V are calculated. Formulas are filled down to row 400.
A9: Dashboard | B9: KPIs, aging by severity, monthly close-out trend with chart, root-cause Pareto and a summary by area.
A10: Repeat Analysis | B10: Equipment / root-cause pairs that have repeated, with record count, repeats, last occurrence and CAPA effectiveness.
A12: HOW TO USE
A13: Add a deviation | B13: Type in the next empty row of Deviation Log: ID, opened date, area, equipment, severity, root cause and owner. Area, severity and root cause have drop-downs.
A14: Close a deviation | B14: Enter the closed date in column H. Status, days open and overdue flag update automatically.
A15: Raise a CAPA | B15: Enter the CAPA number in column I. CAPA due date = deviation closed + the CAPA due days on Settings.
A16: Close a CAPA | B16: Enter the CAPA closed date in column J. The effectiveness result starts as "Check pending" and becomes "Effective" after the check window, or "Ineffective" if the same root cause comes back on the same equipment.
A17: Roll forward | B17: Change "Data as of" on Settings to today (or use =TODAY()).
A19: COLOUR KEY
A20: Blue text | B20: Inputs you type in.
A21: Black text | B21: Formulas. Do not overwrite.
A22: Yellow fill | B22: Settings you can change.
A23: Red row | B23: Open and past the closure target (overdue).
A24: Amber row | B24: Open and past the warning threshold (due soon).
A26: DEFINITIONS
A27: Overdue | B27: Open, and days open is greater than the closure target.
A28: Repeat | B28: Same root cause on the same equipment / process within the repeat window before this deviation was opened.
A29: CAPA effectiveness | B29: Ineffective if the same root cause recurs on the same equipment / process within the effectiveness window after the CAPA closed. Effective once the window has passed with no recurrence. Otherwise Check pending.
A30: Median days to close | B30: Median of days from opened to closed, for records closed in the period. Median is used because a few long investigations would distort an average.

Sheet Dashboard
A1: Deviation and CAPA Dashboard
A2: All figures are formulas on the Deviation Log and Settings sheets.
A3: =" Data as of "&TEXT(AsOf,"dd mmm yyyy")&" · closure target "&Target&" days" -> Data as of 30 Sep 2026 · closure target 30 days
A4: Key figures | B4: Value | H4: Aging of open deviations (days open)
A5: Total deviations | B5: =COUNTA('Deviation Log'!$A$5:$A$400) -> 167 | H5: Severity | I5: 0-30 | J5: 31-60 | K5: 61-90 | L5: 90+ | M5: Total
A6: Open deviations | B6: =COUNTIF('Deviation Log'!$K$5:$K$400,"Open") -> 13 | H6: Critical | I6: =COUNTIFS('Deviation Log'!$E$5:$E$400,"Critical",'Deviation Log'!$N$5:$N$400,"0-30") -> 0 | J6: =COUNTIFS('Deviation Log'!$E$5:$E$400,"Critical",'Deviation Log'!$N$5:$N$400,"31-60") -> 1 | K6: =COUNTIFS('Deviation Log'!$E$5:$E$400,"Critical",'Deviation Log'!$N$5:$N$400,"61-90") -> 0 | L6: =COUNTIFS('Deviation Log'!$E$5:$E$400,"Critical",'Deviation Log'!$N$5:$N$400,"90+") -> 1 | M6: =SUM(I6:L6) -> 2
A7: Overdue (open past target) | B7: =COUNTIF('Deviation Log'!$M$5:$M$400,"Yes") -> 7 | H7: Major | I7: =COUNTIFS('Deviation Log'!$E$5:$E$400,"Major",'Deviation Log'!$N$5:$N$400,"0-30") -> 3 | J7: =COUNTIFS('Deviation Log'!$E$5:$E$400,"Major",'Deviation Log'!$N$5:$N$400,"31-60") -> 2 | K7: =COUNTIFS('Deviation Log'!$E$5:$E$400,"Major",'Deviation Log'!$N$5:$N$400,"61-90") -> 0 | L7: =COUNTIFS('Deviation Log'!$E$5:$E$400,"Major",'Deviation Log'!$N$5:$N$400,"90+") -> 0 | M7: =SUM(I7:L7) -> 5
A8: Critical deviations open | B8: =COUNTIFS('Deviation Log'!$E$5:$E$400,"Critical",'Deviation Log'!$K$5:$K$400,"Open") -> 2 | H8: Minor | I8: =COUNTIFS('Deviation Log'!$E$5:$E$400,"Minor",'Deviation Log'!$N$5:$N$400,"0-30") -> 3 | J8: =COUNTIFS('Deviation Log'!$E$5:$E$400,"Minor",'Deviation Log'!$N$5:$N$400,"31-60") -> 3 | K8: =COUNTIFS('Deviation Log'!$E$5:$E$400,"Minor",'Deviation Log'!$N$5:$N$400,"61-90") -> 0 | L8: =COUNTIFS('Deviation Log'!$E$5:$E$400,"Minor",'Deviation Log'!$N$5:$N$400,"90+") -> 0 | M8: =SUM(I8:L8) -> 6
A9: Median days to close, last 90 days | B9: =IFERROR(MEDIAN('Deviation Log'!$U$5:$U$400),"-") -> 35.5 | H9: All | I9: =COUNTIFS('Deviation Log'!$N$5:$N$400,"0-30") -> 6 | J9: =COUNTIFS('Deviation Log'!$N$5:$N$400,"31-60") -> 6 | K9: =COUNTIFS('Deviation Log'!$N$5:$N$400,"61-90") -> 0 | L9: =COUNTIFS('Deviation Log'!$N$5:$N$400,"90+") -> 1 | M9: =SUM(I9:L9) -> 13
A10: Median days to close, prior 6 months | B10: =IFERROR(MEDIAN('Deviation Log'!$V$5:$V$400),"-") -> 16
A11: Repeat deviations | B11: =COUNTIF('Deviation Log'!$O$5:$O$400,"Yes") -> 9
A12: Repeat rate | B12: =IFERROR(B11/B5,0) -> 0.053892216 | H12: By area
A13: CAPAs raised | B13: =COUNTIF('Deviation Log'!$I$5:$I$400,"?*") -> 46 | H13: Area | I13: Total | J13: Open | K13: Overdue | L13: Repeats | M13: Critical
A14: CAPAs overdue | B14: =COUNTIF('Deviation Log'!$Q$5:$Q$400,"Overdue") -> 0 | H14: Valve assembly | I14: =COUNTIF('Deviation Log'!$C$5:$C$400,H14) -> 46 | J14: =COUNTIFS('Deviation Log'!$C$5:$C$400,H14,'Deviation Log'!$K$5:$K$400,"Open") -> 2 | K14: =COUNTIFS('Deviation Log'!$C$5:$C$400,H14,'Deviation Log'!$M$5:$M$400,"Yes") -> 1 | L14: =COUNTIFS('Deviation Log'!$C$5:$C$400,H14,'Deviation Log'!$O$5:$O$400,"Yes") -> 1 | M14: =COUNTIFS('Deviation Log'!$C$5:$C$400,H14,'Deviation Log'!$E$5:$E$400,"Critical") -> 2
A15: CAPAs with effectiveness result | B15: =COUNTIF('Deviation Log'!$R$5:$R$400,"Effective")+COUNTIF('Deviation Log'!$R$5:$R$400,"Ineffective") -> 19 | H15: Packaging | I15: =COUNTIF('Deviation Log'!$C$5:$C$400,H15) -> 30 | J15: =COUNTIFS('Deviation Log'!$C$5:$C$400,H15,'Deviation Log'!$K$5:$K$400,"Open") -> 6 | K15: =COUNTIFS('Deviation Log'!$C$5:$C$400,H15,'Deviation Log'!$M$5:$M$400,"Yes") -> 3 | L15: =COUNTIFS('Deviation Log'!$C$5:$C$400,H15,'Deviation Log'!$O$5:$O$400,"Yes") -> 3 | M15: =COUNTIFS('Deviation Log'!$C$5:$C$400,H15,'Deviation Log'!$E$5:$E$400,"Critical") -> 1
A16: CAPAs ineffective | B16: =COUNTIF('Deviation Log'!$R$5:$R$400,"Ineffective") -> 2 | H16: Sterilization | I16: =COUNTIF('Deviation Log'!$C$5:$C$400,H16) -> 20 | J16: =COUNTIFS('Deviation Log'!$C$5:$C$400,H16,'Deviation Log'!$K$5:$K$400,"Open") -> 1 | K16: =COUNTIFS('Deviation Log'!$C$5:$C$400,H16,'Deviation Log'!$M$5:$M$400,"Yes") -> 1 | L16: =COUNTIFS('Deviation Log'!$C$5:$C$400,H16,'Deviation Log'!$O$5:$O$400,"Yes") -> 1 | M16: =COUNTIFS('Deviation Log'!$C$5:$C$400,H16,'Deviation Log'!$E$5:$E$400,"Critical") -> 2
A17: CAPA effectiveness rate | B17: =IFERROR((B15-B16)/B15,0) -> 0.89473684 | H17: QC Microbiology | I17: =COUNTIF('Deviation Log'!$C$5:$C$400,H17) -> 36 | J17: =COUNTIFS('Deviation Log'!$C$5:$C$400,H17,'Deviation Log'!$K$5:$K$400,"Open") -> 2 | K17: =COUNTIFS('Deviation Log'!$C$5:$C$400,H17,'Deviation Log'!$M$5:$M$400,"Yes") -> 1 | L17: =COUNTIFS('Deviation Log'!$C$5:$C$400,H17,'Deviation Log'!$O$5:$O$400,"Yes") -> 3 | M17: =COUNTIFS('Deviation Log'!$C$5:$C$400,H17,'Deviation Log'!$E$5:$E$400,"Critical") -> 0
H18: Warehouse | I18: =COUNTIF('Deviation Log'!$C$5:$C$400,H18) -> 15 | J18: =COUNTIFS('Deviation Log'!$C$5:$C$400,H18,'Deviation Log'!$K$5:$K$400,"Open") -> 1 | K18: =COUNTIFS('Deviation Log'!$C$5:$C$400,H18,'Deviation Log'!$M$5:$M$400,"Yes") -> 0 | L18: =COUNTIFS('Deviation Log'!$C$5:$C$400,H18,'Deviation Log'!$O$5:$O$400,"Yes") -> 0 | M18: =COUNTIFS('Deviation Log'!$C$5:$C$400,H18,'Deviation Log'!$E$5:$E$400,"Critical") -> 0
H19: Facilities | I19: =COUNTIF('Deviation Log'!$C$5:$C$400,H19) -> 20 | J19: =COUNTIFS('Deviation Log'!$C$5:$C$400,H19,'Deviation Log'!$K$5:$K$400,"Open") -> 1 | K19: =COUNTIFS('Deviation Log'!$C$5:$C$400,H19,'Deviation Log'!$M$5:$M$400,"Yes") -> 1 | L19: =COUNTIFS('Deviation Log'!$C$5:$C$400,H19,'Deviation Log'!$O$5:$O$400,"Yes") -> 1 | M19: =COUNTIFS('Deviation Log'!$C$5:$C$400,H19,'Deviation Log'!$E$5:$E$400,"Critical") -> 2
A21: Monthly close-out trend
A22: Month | B22: Opened | C22: Closed | D22: Median days to close | E22: Target (days) | F22: Open at month end
A23: 45748 | B23: =COUNTIF('Deviation Log'!$S$5:$S$400,A23) -> 10 | C23: =COUNTIF('Deviation Log'!$T$5:$T$400,A23) -> 3 | D23: {=IFERROR(MEDIAN(IF('Deviation Log'!$T$5:$T$400=A23,'Deviation Log'!$L$5:$L$400)),NA())} -> 20 | E23: =Target -> 30 | F23: =COUNTIFS('Deviation Log'!$B$5:$B$400,"<="&EOMONTH(A23,0),'Deviation Log'!$A$5:$A$400,"<>")-COUNTIFS('Deviation Log'!$H$5:$H$400,"<="&EOMONTH(A23,0)) -> 7
A24: 45778 | B24: =COUNTIF('Deviation Log'!$S$5:$S$400,A24) -> 9 | C24: =COUNTIF('Deviation Log'!$T$5:$T$400,A24) -> 11 | D24: {=IFERROR(MEDIAN(IF('Deviation Log'!$T$5:$T$400=A24,'Deviation Log'!$L$5:$L$400)),NA())} -> 23 | E24: =Target -> 30 | F24: =COUNTIFS('Deviation Log'!$B$5:$B$400,"<="&EOMONTH(A24,0),'Deviation Log'!$A$5:$A$400,"<>")-COUNTIFS('Deviation Log'!$H$5:$H$400,"<="&EOMONTH(A24,0)) -> 5
A25: 45809 | B25: =COUNTIF('Deviation Log'!$S$5:$S$400,A25) -> 10 | C25: =COUNTIF('Deviation Log'!$T$5:$T$400,A25) -> 7 | D25: {=IFERROR(MEDIAN(IF('Deviation Log'!$T$5:$T$400=A25,'Deviation Log'!$L$5:$L$400)),NA())} -> 18 | E25: =Target -> 30 | F25: =COUNTIFS('Deviation Log'!$B$5:$B$400,"<="&EOMONTH(A25,0),'Deviation Log'!$A$5:$A$400,"<>")-COUNTIFS('Deviation Log'!$H$5:$H$400,"<="&EOMONTH(A25,0)) -> 8
A26: 45839 | B26: =COUNTIF('Deviation Log'!$S$5:$S$400,A26) -> 10 | C26: =COUNTIF('Deviation Log'!$T$5:$T$400,A26) -> 14 | D26: {=IFERROR(MEDIAN(IF('Deviation Log'!$T$5:$T$400=A26,'Deviation Log'!$L$5:$L$400)),NA())} -> 19.5 | E26: =Target -> 30 | F26: =COUNTIFS('Deviation Log'!$B$5:$B$400,"<="&EOMONTH(A26,0),'Deviation Log'!$A$5:$A$400,"<>")-COUNTIFS('Deviation Log'!$H$5:$H$400,"<="&EOMONTH(A26,0)) -> 4
A27: 45870 | B27: =COUNTIF('Deviation Log'!$S$5:$S$400,A27) -> 8 | C27: =COUNTIF('Deviation Log'!$T$5:$T$400,A27) -> 8 | D27: {=IFERROR(MEDIAN(IF('Deviation Log'!$T$5:$T$400=A27,'Deviation Log'!$L$5:$L$400)),NA())} -> 18 | E27: =Target -> 30 | F27: =COUNTIFS('Deviation Log'!$B$5:$B$400,"<="&EOMONTH(A27,0),'Deviation Log'!$A$5:$A$400,"<>")-COUNTIFS('Deviation Log'!$H$5:$H$400,"<="&EOMONTH(A27,0)) -> 4
A28: 45901 | B28: =COUNTIF('Deviation Log'!$S$5:$S$400,A28) -> 8 | C28: =COUNTIF('Deviation Log'!$T$5:$T$400,A28) -> 8 | D28: {=IFERROR(MEDIAN(IF('Deviation Log'!$T$5:$T$400=A28,'Deviation Log'!$L$5:$L$400)),NA())} -> 18 | E28: =Target -> 30 | F28: =COUNTIFS('Deviation Log'!$B$5:$B$400,"<="&EOMONTH(A28,0),'Deviation Log'!$A$5:$A$400,"<>")-COUNTIFS('Deviation Log'!$H$5:$H$400,"<="&EOMONTH(A28,0)) -> 4
A29: 45931 | B29: =COUNTIF('Deviation Log'!$S$5:$S$400,A29) -> 12 | C29: =COUNTIF('Deviation Log'!$T$5:$T$400,A29) -> 6 | D29: {=IFERROR(MEDIAN(IF('Deviation Log'!$T$5:$T$400=A29,'Deviation Log'!$L$5:$L$400)),NA())} -> 15.5 | E29: =Target -> 30 | F29: =COUNTIFS('Deviation Log'!$B$5:$B$400,"<="&EOMONTH(A29,0),'Deviation Log'!$A$5:$A$400,"<>")-COUNTIFS('Deviation Log'!$H$5:$H$400,"<="&EOMONTH(A29,0)) -> 10
A30: 45962 | B30: =COUNTIF('Deviation Log'!$S$5:$S$400,A30) -> 7 | C30: =COUNTIF('Deviation Log'!$T$5:$T$400,A30) -> 13 | D30: {=IFERROR(MEDIAN(IF('Deviation Log'!$T$5:$T$400=A30,'Deviation Log'!$L$5:$L$400)),NA())} -> 20 | E30: =Target -> 30 | F30: =COUNTIFS('Deviation Log'!$B$5:$B$400,"<="&EOMONTH(A30,0),'Deviation Log'!$A$5:$A$400,"<>")-COUNTIFS('Deviation Log'!$H$5:$H$400,"<="&EOMONTH(A30,0)) -> 4
A31: 45992 | B31: =COUNTIF('Deviation Log'!$S$5:$S$400,A31) -> 7 | C31: =COUNTIF('Deviation Log'!$T$5:$T$400,A31) -> 9 | D31: {=IFERROR(MEDIAN(IF('Deviation Log'!$T$5:$T$400=A31,'Deviation Log'!$L$5:$L$400)),NA())} -> 18 | E31: =Target -> 30 | F31: =COUNTIFS('Deviation Log'!$B$5:$B$400,"<="&EOMONTH(A31,0),'Deviation Log'!$A$5:$A$400,"<>")-COUNTIFS('Deviation Log'!$H$5:$H$400,"<="&EOMONTH(A31,0)) -> 2
A32: 46023 | B32: =COUNTIF('Deviation Log'!$S$5:$S$400,A32) -> 11 | C32: =COUNTIF('Deviation Log'!$T$5:$T$400,A32) -> 6 | D32: {=IFERROR(MEDIAN(IF('Deviation Log'!$T$5:$T$400=A32,'Deviation Log'!$L$5:$L$400)),NA())} -> 15.5 | E32: =Target -> 30 | F32: =COUNTIFS('Deviation Log'!$B$5:$B$400,"<="&EOMONTH(A32,0),'Deviation Log'!$A$5:$A$400,"<>")-COUNTIFS('Deviation Log'!$H$5:$H$400,"<="&EOMONTH(A32,0)) -> 7
A33: 46054 | B33: =COUNTIF('Deviation Log'!$S$5:$S$400,A33) -> 9 | C33: =COUNTIF('Deviation Log'!$T$5:$T$400,A33) -> 8 | D33: {=IFERROR(MEDIAN(IF('Deviation Log'!$T$5:$T$400=A33,'Deviation Log'!$L$5:$L$400)),NA())} -> 16 | E33: =Target -> 30 | F33: =COUNTIFS('Deviation Log'!$B$5:$B$400,"<="&EOMONTH(A33,0),'Deviation Log'!$A$5:$A$400,"<>")-COUNTIFS('Deviation Log'!$H$5:$H$400,"<="&EOMONTH(A33,0)) -> 8
A34: 46082 | B34: =COUNTIF('Deviation Log'!$S$5:$S$400,A34) -> 9 | C34: =COUNTIF('Deviation Log'!$T$5:$T$400,A34) -> 13 | D34: {=IFERROR(MEDIAN(IF('Deviation Log'!$T$5:$T$400=A34,'Deviation Log'!$L$5:$L$400)),NA())} -> 15 | E34: =Target -> 30 | F34: =COUNTIFS('Deviation Log'!$B$5:$B$400,"<="&EOMONTH(A34,0),'Deviation Log'!$A$5:$A$400,"<>")-COUNTIFS('Deviation Log'!$H$5:$H$400,"<="&EOMONTH(A34,0)) -> 4
... A40: 46266 | B40: =COUNTIF('Deviation Log'!$S$5:$S$400,A40) -> 7 | C40: =COUNTIF('Deviation Log'!$T$5:$T$400,A40) -> 12 | D40: {=IFERROR(MEDIAN(IF('Deviation Log'!$T$5:$T$400=A40,'Deviation Log'!$L$5:$L$400)),NA())} -> 35.5 | E40: =Target -> 30 | F40: =COUNTIFS('Deviation Log'!$B$5:$B$400,"<="&EOMONTH(A40,0),'Deviation Log'!$A$5:$A$400,"<>")-COUNTIFS('Deviation Log'!$H$5:$H$400,"<="&EOMONTH(A40,0)) -> 13
A41: Months are inputs: extend the list down and copy the formulas to add a month. If nothing closed in a month the median is left blank as a chart gap (NA).
A44: Root cause Pareto
A45: Root cause | B45: Count | C45: % of total | D45: Cumulative %
A46: GDP / documentation error | B46: =COUNTIF('Deviation Log'!$F$5:$F$400,A46) -> 38 | C46: =IFERROR(B46/$B$5,0) -> 0.22754491 | D46: =SUM($C$46:C46) -> 0.22754491
A47: Equipment malfunction | B47: =COUNTIF('Deviation Log'!$F$5:$F$400,A47) -> 28 | C47: =IFERROR(B47/$B$5,0) -> 0.16766467 | D47: =SUM($C$46:C47) -> 0.39520958
A48: Procedure not followed | B48: =COUNTIF('Deviation Log'!$F$5:$F$400,A48) -> 21 | C48: =IFERROR(B48/$B$5,0) -> 0.1257485 | D48: =SUM($C$46:C48) -> 0.52095808
...

Sheet Settings
A1: Settings
A2: Change the yellow cells. Everything else in the workbook reads from here.
B4: Setting | C4: Value
B5: Data as of | C5: 46295 | D5: Date the tracker is reported as of. Use =TODAY() for a live tracker.
B6: Closure target (days) | C6: 30 | D6: Deviations should be investigated and closed within this many calendar days.
B7: Due-soon warning (days) | C7: 20 | D7: Open records past this age are highlighted amber.
B8: CAPA due after deviation close (days) | C8: 90 | D8: CAPA due date = deviation closed date + this.
B9: Repeat window (days) | C9: 180 | D9: Same cause on the same equipment within this window counts as a repeat.
B10: Effectiveness check window (days) | C10: 180 | D10: CAPA is judged effective if the cause does not recur within this window after CAPA closure.
B12: Drop-down lists (add new values to the bottom of a list)
B13: Areas | C13: Severities | D13: RootCauses | E13: Owners
B14: Valve assembly | C14: Minor | D14: Calibration overdue | E14: D. Kim
B15: Packaging | C15: Major | D15: Environmental excursion | E15: J. Alvarez
B16: Sterilization | C16: Critical | D16: Equipment malfunction | E16: K. Tran
B17: QC Microbiology | D17: GDP / documentation error | E17: L. Haddad
B18: Warehouse | D18: Labeling error | E18: M. Chen
B19: Facilities | D19: Line clearance not performed | E19: R. Patel
D20: Preventive maintenance missed | E20: S. Okafor
D21: Procedure not followed
D22: Sample handling error
D23: Supplier material defect
D24: Temperature excursion
D25: Training gap

Sheet Deviation Log
A1: Deviation Log
A2: Blue columns A to J are inputs. Grey-headed columns K to V are calculated; do not type over them.
A4: Deviation ID | B4: Opened | C4: Area | D4: Equipment / process | E4: Severity | F4: Root cause | G4: Owner | H4: Closed | I4: CAPA ID | J4: CAPA closed | K4: Status | L4: Days open | M4: Overdue | N4: Aging bucket (open) | O4: Repeat | P4: CAPA due | Q4: CAPA status | R4: CAPA effectiveness | S4: Opened month | T4: Closed month | U4: Days to close, last 90 d | V4: Days to close, prior 6 mo
A5: DEV-25-0101 | B5: 45748 | C5: Valve assembly | D5: Final inspection bench | E5: Minor | F5: GDP / documentation error | G5: K. Tran | H5: 45772 | K5: =IF(A5="","",IF(H5="","Open","Closed")) -> Closed | L5: =IF(A5="","",IF(H5="",AsOf-B5,H5-B5)) -> 24 | M5: =IF(A5="","",IF(AND(K5="Open",L5>Target),"Yes","No")) -> No | N5: =IF(K5<>"Open","",IF(L5<=30,"0-30",IF(L5<=60,"31-60",IF(L5<=90,"61-90","90+")))) | O5: =IF(A5="","",IF(COUNTIFS($D$5:$D$400,D5,$F$5:$F$400,F5,$B$5:$B$400,">="&(B5-RepeatWin),$B$5:$B$400,"<"&B5)>0,"Yes","No")) -> No | P5: =IF(OR(I5="",H5=""),"",H5+CapaDue) | Q5: =IF(A5="","",IF(I5="","Not required",IF(J5<>"","Closed",IF(H5="","Awaiting dev. close",IF(AsOf>P5,"Overdue","Open"))))) -> Not required | R5: =IF(J5="","",IF(COUNTIFS($D$5:$D$400,D5,$F$5:$F$400,F5,$B$5:$B$400,">"&J5,$B$5:$B$400,"<="&(J5+EffWin))>0,"Ineffective",IF(AsOf-J5>=EffWin,"Effective","Check pending"))) | S5: =IF(A5="","",DATE(YEAR(B5),MONTH(B5),1)) -> 45748 | T5: =IF(H5="","",DATE(YEAR(H5),MONTH(H5),1)) -> 45748 | U5: =IF(H5="","",IF(AsOf-H5<=90,L5,"")) | V5: =IF(H5="","",IF(AND(AsOf-H5>90,AsOf-H5<=270),L5,""))
A6: DEV-25-0102 | B6: 45752 | C6: QC Microbiology | D6: Incubator INC-02 | E6: Minor | F6: GDP / documentation error | G6: L. Haddad | H6: 45772 | K6: =IF(A6="","",IF(H6="","Open","Closed")) -> Closed | L6: =IF(A6="","",IF(H6="",AsOf-B6,H6-B6)) -> 20 | M6: =IF(A6="","",IF(AND(K6="Open",L6>Target),"Yes","No")) -> No | N6: =IF(K6<>"Open","",IF(L6<=30,"0-30",IF(L6<=60,"31-60",IF(L6<=90,"61-90","90+")))) | O6: =IF(A6="","",IF(COUNTIFS($D$5:$D$400,D6,$F$5:$F$400,F6,$B$5:$B$400,">="&(B6-RepeatWin),$B$5:$B$400,"<"&B6)>0,"Yes","No")) -> No | P6: =IF(OR(I6="",H6=""),"",H6+CapaDue) | Q6: =IF(A6="","",IF(I6="","Not required",IF(J6<>"","Closed",IF(H6="","Awaiting dev. close",IF(AsOf>P6,"Overdue","Open"))))) -> Not required | R6: =IF(J6="","",IF(COUNTIFS($D$5:$D$400,D6,$F$5:$F$400,F6,$B$5:$B$400,">"&J6,$B$5:$B$400,"<="&(J6+EffWin))>0,"Ineffective",IF(AsOf-J6>=EffWin,"Effective","Check pending"))) | S6: =IF(A6="","",DATE(YEAR(B6),MONTH(B6),1)) -> 45748 | T6: =IF(H6="","",DATE(YEAR(H6),MONTH(H6),1)) -> 45748 | U6: =IF(H6="","",IF(AsOf-H6<=90,L6,"")) | V6: =IF(H6="","",IF(AND(AsOf-H6>90,AsOf-H6<=270),L6,""))
A7: DEV-25-0103 | B7: 45757 | C7: Packaging | D7: Carton printer CP-1 | E7: Minor | F7: Equipment malfunction | G7: S. Okafor | H7: 45770 | K7: =IF(A7="","",IF(H7="","Open","Closed")) -> Closed | L7: =IF(A7="","",IF(H7="",AsOf-B7,H7-B7)) -> 13 | M7: =IF(A7="","",IF(AND(K7="Open",L7>Target),"Yes","No")) -> No | N7: =IF(K7<>"Open","",IF(L7<=30,"0-30",IF(L7<=60,"31-60",IF(L7<=90,"61-90","90+")))) | O7: =IF(A7="","",IF(COUNTIFS($D$5:$D$400,D7,$F$5:$F$400,F7,$B$5:$B$400,">="&(B7-RepeatWin),$B$5:$B$400,"<"&B7)>0,"Yes","No")) -> No | P7: =IF(OR(I7="",H7=""),"",H7+CapaDue) | Q7: =IF(A7="","",IF(I7="","Not required",IF(J7<>"","Closed",IF(H7="","Awaiting dev. close",IF(AsOf>P7,"Overdue","Open"))))) -> Not required | R7: =IF(J7="","",IF(COUNTIFS($D$5:$D$400,D7,$F$5:$F$400,F7,$B$5:$B$400,">"&J7,$B$5:$B$400,"<="&(J7+EffWin))>0,"Ineffective",IF(AsOf-J7>=EffWin,"Effective","Check pending"))) | S7: =IF(A7="","",DATE(YEAR(B7),MONTH(B7),1)) -> 45748 | T7: =IF(H7="","",DATE(YEAR(H7),MONTH(H7),1)) -> 45748 | U7: =IF(H7="","",IF(AsOf-H7<=90,L7,"")) | V7: =IF(H7="","",IF(AND(AsOf-H7>90,AsOf-H7<=270),L7,""))
A8: DEV-25-0104 | B8: 45758 | C8: Facilities | D8: Cleanroom HVAC AHU-3 | E8: Minor | F8: Preventive maintenance missed | G8: S. Okafor | H8: 45783 | K8: =IF(A8="","",IF(H8="","Open","Closed")) -> Closed | L8: =IF(A8="","",IF(H8="",AsOf-B8,H8-B8)) -> 25 | M8: =IF(A8="","",IF(AND(K8="Open",L8>Target),"Yes","No")) -> No | N8: =IF(K8<>"Open","",IF(L8<=30,"0-30",IF(L8<=60,"31-60",IF(L8<=90,"61-90","90+")))) | O8: =IF(A8="","",IF(COUNTIFS($D$5:$D$400,D8,$F$5:$F$400,F8,$B$5:$B$400,">="&(B8-RepeatWin),$B$5:$B$400,"<"&B8)>0,"Yes","No")) -> No | P8: =IF(OR(I8="",H8=""),"",H8+CapaDue) | Q8: =IF(A8="","",IF(I8="","Not required",IF(J8<>"","Closed",IF(H8="","Awaiting dev. close",IF(AsOf>P8,"Overdue","Open"))))) -> Not required | R8: =IF(J8="","",IF(COUNTIFS($D$5:$D$400,D8,$F$5:$F$400,F8,$B$5:$B$400,">"&J8,$B$5:$B$400,"<="&(J8+EffWin))>0,"Ineffective",IF(AsOf-J8>=EffWin,"Effective","Check pending"))) | S8: =IF(A8="","",DATE(YEAR(B8),MONTH(B8),1)) -> 45748 | T8: =IF(H8="","",DATE(YEAR(H8),MONTH(H8),1)) -> 45778 | U8: =IF(H8="","",IF(AsOf-H8<=90,L8,"")) | V8: =IF(H8="","",IF(AND(AsOf-H8>90,AsOf-H8<=270),L8,""))
A9: DEV-25-0105 | B9: 45762 | C9: QC Microbiology | D9: Incubator INC-02 | E9: Minor | F9: Training gap | G9: D. Kim | H9: 45783 | K9: =IF(A9="","",IF(H9="","Open","Closed")) -> Closed | L9: =IF(A9="","",IF(H9="",AsOf-B9,H9-B9)) -> 21 | M9: =IF(A9="","",IF(AND(K9="Open",L9>Target),"Yes","No")) -> No | N9: =IF(K9<>"Open","",IF(L9<=30,"0-30",IF(L9<=60,"31-60",IF(L9<=90,"61-90","90+")))) | O9: =IF(A9="","",IF(COUNTIFS($D$5:$D$400,D9,$F$5:$F$400,F9,$B$5:$B$400,">="&(B9-RepeatWin),$B$5:$B$400,"<"&B9)>0,"Yes","No")) -> No | P9: =IF(OR(I9="",H9=""),"",H9+CapaDue) | Q9: =IF(A9="","",IF(I9="","Not required",IF(J9<>"","Closed",IF(H9="","Awaiting dev. close",IF(AsOf>P9,"Overdue","Open"))))) -> Not required | R9: =IF(J9="","",IF(COUNTIFS($D$5:$D$400,D9,$F$5:$F$400,F9,$B$5:$B$400,">"&J9,$B$5:$B$400,"<="&(J9+EffWin))>0,"Ineffective",IF(AsOf-J9>=EffWin,"Effective","Check pending"))) | S9: =IF(A9="","",DATE(YEAR(B9),MONTH(B9),1)) -> 45748 | T9: =IF(H9="","",DATE(YEAR(H9),MONTH(H9),1)) -> 45778 | U9: =IF(H9="","",IF(AsOf-H9<=90,L9,"")) | V9: =IF(H9="","",IF(AND(AsOf-H9>90,AsOf-H9<=270),L9,""))
A10: DEV-25-0106 | B10: 45763 | C10: Valve assembly | D10: Frame crimping station | E10: Major | F10: Equipment malfunction | G10: L. Haddad | H10: 45786 | I10: CAPA-001 | J10: 45843 | K10: =IF(A10="","",IF(H10="","Open","Closed")) -> Closed | L10: =IF(A10="","",IF(H10="",AsOf-B10,H10-B10)) -> 23 | M10: =IF(A10="","",IF(AND(K10="Open",L10>Target),"Yes","No")) -> No | N10: =IF(K10<>"Open","",IF(L10<=30,"0-30",IF(L10<=60,"31-60",IF(L10<=90,"61-90","90+")))) | O10: =IF(A10="","",IF(COUNTIFS($D$5:$D$400,D10,$F$5:$F$400,F10,$B$5:$B$400,">="&(B10-RepeatWin),$B$5:$B$400,"<"&B10)>0,"Yes","No")) -> No | P10: =IF(OR(I10="",H10=""),"",H10+CapaDue) -> 45876 | Q10: =IF(A10="","",IF(I10="","Not required",IF(J10<>"","Closed",IF(H10="","Awaiting dev. close",IF(AsOf>P10,"Overdue","Open"))))) -> Closed | R10: =IF(J10="","",IF(COUNTIFS($D$5:$D$400,D10,$F$5:$F$400,F10,$B$5:$B$400,">"&J10,$B$5:$B$400,"<="&(J10+EffWin))>0,"Ineffective",IF(AsOf-J10>=EffWin,"Effective","Check pending"))) -> Effective | S10: =IF(A10="","",DATE(YEAR(B10),MONTH(B10),1)) -> 45748 | T10: =IF(H10="","",DATE(YEAR(H10),MONTH(H10),1)) -> 45778 | U10: =IF(H10="","",IF(AsOf-H10<=90,L10,"")) | V10: =IF(H10="","",IF(AND(AsOf-H10>90,AsOf-H10<=270),L10,""))
A11: DEV-25-0107 | B11: 45764 | C11: Packaging | D11: Packaging line PL-2 | E11: Major | F11: GDP / documentation error | G11: L. Haddad | H11: 45794 | I11: CAPA-002 | J11: 45834 | K11: =IF(A11="","",IF(H11="","Open","Closed")) -> Closed | L11: =IF(A11="","",IF(H11="",AsOf-B11,H11-B11)) -> 30 | M11: =IF(A11="","",IF(AND(K11="Open",L11>Target),"Yes","No")) -> No | N11: =IF(K11<>"Open","",IF(L11<=30,"0-30",IF(L11<=60,"31-60",IF(L11<=90,"61-90","90+")))) | O11: =IF(A11="","",IF(COUNTIFS($D$5:$D$400,D11,$F$5:$F$400,F11,$B$5:$B$400,">="&(B11-RepeatWin),$B$5:$B$400,"<"&B11)>0,"Yes","No")) -> No | P11: =IF(OR(I11="",H11=""),"",H11+CapaDue) -> 45884 | Q11: =IF(A11="","",IF(I11="","Not required",IF(J11<>"","Closed",IF(H11="","Awaiting dev. close",IF(AsOf>P11,"Overdue","Open"))))) -> Closed | R11: =IF(J11="","",IF(COUNTIFS($D$5:$D$400,D11,$F$5:$F$400,F11,$B$5:$B$400,">"&J11,$B$5:$B$400,"<="&(J11+EffWin))>0,"Ineffective",IF(AsOf-J11>=EffWin,"Effective","Check pending"))) -> Effective | S11: =IF(A11="","",DATE(YEAR(B11),MONTH(B11),1)) -> 45748 | T11: =IF(H11="","",DATE(YEAR(H11),MONTH(H11),1)) -> 45778 | U11: =IF(H11="","",IF(AsOf-H11<=90,L11,"")) | V11: =IF(H11="","",IF(AND(AsOf-H11>90,AsOf-H11<=270),L11,""))
A12: DEV-25-0108 | B12: 45770 | C12: Valve assembly | D12: Tissue rinse station | E12: Minor | F12: Procedure not followed | G12: K. Tran | H12: 45794 | K12: =IF(A12="","",IF(H12="","Open","Closed")) -> Closed | L12: =IF(A12="","",IF(H12="",AsOf-B12,H12-B12)) -> 24 | M12: =IF(A12="","",IF(AND(K12="Open",L12>Target),"Yes","No")) -> No | N12: =IF(K12<>"Open","",IF(L12<=30,"0-30",IF(L12<=60,"31-60",IF(L12<=90,"61-90","90+")))) | O12: =IF(A12="","",IF(COUNTIFS($D$5:$D$400,D12,$F$5:$F$400,F12,$B$5:$B$400,">="&(B12-RepeatWin),$B$5:$B$400,"<"&B12)>0,"Yes","No")) -> No | P12: =IF(OR(I12="",H12=""),"",H12+CapaDue) | Q12: =IF(A12="","",IF(I12="","Not required",IF(J12<>"","Closed",IF(H12="","Awaiting dev. close",IF(AsOf>P12,"Overdue","Open"))))) -> Not required | R12: =IF(J12="","",IF(COUNTIFS($D$5:$D$400,D12,$F$5:$F$400,F12,$B$5:$B$400,">"&J12,$B$5:$B$400,"<="&(J12+EffWin))>0,"Ineffective",IF(AsOf-J12>=EffWin,"Effective","Check pending"))) | S12: =IF(A12="","",DATE(YEAR(B12),MONTH(B12),1)) -> 45748 | T12: =IF(H12="","",DATE(YEAR(H12),MONTH(H12),1)) -> 45778 | U12: =IF(H12="","",IF(AsOf-H12<=90,L12,"")) | V12: =IF(H12="","",IF(AND(AsOf-H12>90,AsOf-H12<=270),L12,""))
A13: DEV-25-0109 | B13: 45772 | C13: QC Microbiology | D13: Media preparation | E13: Minor | F13: Training gap | G13: K. Tran | H13: 45786 | K13: =IF(A13="","",IF(H13="","Open","Closed")) -> Closed | L13: =IF(A13="","",IF(H13="",AsOf-B13,H13-B13)) -> 14 | M13: =IF(A13="","",IF(AND(K13="Open",L13>Target),"Yes","No")) -> No | N13: =IF(K13<>"Open","",IF(L13<=30,"0-30",IF(L13<=60,"31-60",IF(L13<=90,"61-90","90+")))) | O13: =IF(A13="","",IF(COUNTIFS($D$5:$D$400,D13,$F$5:$F$400,F13,$B$5:$B$400,">="&(B13-RepeatWin),$B$5:$B$400,"<"&B13)>0,"Yes","No")) -> No | P13: =IF(OR(I13="",H13=""),"",H13+CapaDue) | Q13: =IF(A13="","",IF(I13="","Not required",IF(J13<>"","Closed",IF(H13="","Awaiting dev. close",IF(AsOf>P13,"Overdue","Open"))))) -> Not required | R13: =IF(J13="","",IF(COUNTIFS($D$5:$D$400,D13,$F$5:$F$400,F13,$B$5:$B$400,">"&J13,$B$5:$B$400,"<="&(J13+EffWin))>0,"Ineffective",IF(AsOf-J13>=EffWin,"Effective","Check pending"))) | S13: =IF(A13="","",DATE(YEAR(B13),MONTH(B13),1)) -> 45748 | T13: =IF(H13="","",DATE(YEAR(H13),MONTH(H13),1)) -> 45778 | U13: =IF(H13="","",IF(AsOf-H13<=90,L13,"")) | V13: =IF(H13="","",IF(AND(AsOf-H13>90,AsOf-H13<=270),L13,""))
A14: DEV-25-0110 | B14: 45775 | C14: Facilities | D14: Cleanroom HVAC AHU-2 | E14: Critical | F14: Environmental excursion | G14: R. Patel | H14: 45799 | I14: CAPA-003 | J14: 45891 | K14: =IF(A14="","",IF(H14="","Open","Closed")) -> Closed | L14: =IF(A14="","",IF(H14="",AsOf-B14,H14-B14)) -> 24 | M14: =IF(A14="","",IF(AND(K14="Open",L14>Target),"Yes","No")) -> No | N14: =IF(K14<>"Open","",IF(L14<=30,"0-30",IF(L14<=60,"31-60",IF(L14<=90,"61-90","90+")))) | O14: =IF(A14="","",IF(COUNTIFS($D$5:$D$400,D14,$F$5:$F$400,F14,$B$5:$B$400,">="&(B14-RepeatWin),$B$5:$B$400,"<"&B14)>0,"Yes","No")) -> No | P14: =IF(OR(I14="",H14=""),"",H14+CapaDue) -> 45889 | Q14: =IF(A14="","",IF(I14="","Not required",IF(J14<>"","Closed",IF(H14="","Awaiting dev. close",IF(AsOf>P14,"Overdue","Open"))))) -> Closed | R14: =IF(J14="","",IF(COUNTIFS($D$5:$D$400,D14,$F$5:$F$400,F14,$B$5:$B$400,">"&J14,$B$5:$B$400,"<="&(J14+EffWin))>0,"Ineffective",IF(AsOf-J14>=EffWin,"Effective","Check pending"))) -> Effective | S14: =IF(A14="","",DATE(YEAR(B14),MONTH(B14),1)) -> 45748 | T14: =IF(H14="","",DATE(YEAR(H14),MONTH(H14),1)) -> 45778 | U14: =IF(H14="","",IF(AsOf-H14<=90,L14,"")) | V14: =IF(H14="","",IF(AND(AsOf-H14>90,AsOf-H14<=270),L14,""))
A15: DEV-25-0111 | B15: 45781 | C15: Facilities | D15: WFI loop | E15: Major | F15: Equipment malfunction | G15: R. Patel | H15: 45804 | I15: CAPA-004 | J15: 45881 | K15: =IF(A15="","",IF(H15="","Open","Closed")) -> Closed | L15: =IF(A15="","",IF(H15="",AsOf-B15,H15-B15)) -> 23 | M15: =IF(A15="","",IF(AND(K15="Open",L15>Target),"Yes","No")) -> No | N15: =IF(K15<>"Open","",IF(L15<=30,"0-30",IF(L15<=60,"31-60",IF(L15<=90,"61-90","90+")))) | O15: =IF(A15="","",IF(COUNTIFS($D$5:$D$400,D15,$F$5:$F$400,F15,$B$5:$B$400,">="&(B15-RepeatWin),$B$5:$B$400,"<"&B15)>0,"Yes","No")) -> No | P15: =IF(OR(I15="",H15=""),"",H15+CapaDue) -> 45894 | Q15: =IF(A15="","",IF(I15="","Not required",IF(J15<>"","Closed",IF(H15="","Awaiting dev. close",IF(AsOf>P15,"Overdue","Open"))))) -> Closed | R15: =IF(J15="","",IF(COUNTIFS($D$5:$D$400,D15,$F$5:$F$400,F15,$B$5:$B$400,">"&J15,$B$5:$B$400,"<="&(J15+EffWin))>0,"Ineffective",IF(AsOf-J15>=EffWin,"Effective","Check pending"))) -> Effective | S15: =IF(A15="","",DATE(YEAR(B15),MONTH(B15),1)) -> 45778 | T15: =IF(H15="","",DATE(YEAR(H15),MONTH(H15),1)) -> 45778 | U15: =IF(H15="","",IF(AsOf-H15<=90,L15,"")) | V15: =IF(H15="","",IF(AND(AsOf-H15>90,AsOf-H15<=270),L15,""))
A16: DEV-25-0112 | B16: 45785 | C16: QC Microbiology | D16: EM sampling | E16: Minor | F16: Training gap | G16: J. Alvarez | H16: 45802 | K16: =IF(A16="","",IF(H16="","Open","Closed")) -> Closed | L16: =IF(A16="","",IF(H16="",AsOf-B16,H16-B16)) -> 17 | M16: =IF(A16="","",IF(AND(K16="Open",L16>Target),"Yes","No")) -> No | N16: =IF(K16<>"Open","",IF(L16<=30,"0-30",IF(L16<=60,"31-60",IF(L16<=90,"61-90","90+")))) | O16: =IF(A16="","",IF(COUNTIFS($D$5:$D$400,D16,$F$5:$F$400,F16,$B$5:$B$400,">="&(B16-RepeatWin),$B$5:$B$400,"<"&B16)>0,"Yes","No")) -> No | P16: =IF(OR(I16="",H16=""),"",H16+CapaDue) | Q16: =IF(A16="","",IF(I16="","Not required",IF(J16<>"","Closed",IF(H16="","Awaiting dev. close",IF(AsOf>P16,"Overdue","Open"))))) -> Not required | R16: =IF(J16="","",IF(COUNTIFS($D$5:$D$400,D16,$F$5:$F$400,F16,$B$5:$B$400,">"&J16,$B$5:$B$400,"<="&(J16+EffWin))>0,"Ineffective",IF(AsOf-J16>=EffWin,"Effective","Check pending"))) | S16: =IF(A16="","",DATE(YEAR(B16),MONTH(B16),1)) -> 45778 | T16: =IF(H16="","",DATE(YEAR(H16),MONTH(H16),1)) -> 45778 | U16: =IF(H16="","",IF(AsOf-H16<=90,L16,"")) | V16: =IF(H16="","",IF(AND(AsOf-H16>90,AsOf-H16<=270),L16,""))
A17: DEV-25-0113 | B17: 45787 | C17: Facilities | D17: Compressed air system | E17: Major | F17: Preventive maintenance missed | G17: J. Alvarez | H17: 45811 | I17: CAPA-005 | J17: 45899 | K17: =IF(A17="","",IF(H17="","Open","Closed")) -> Closed | L17: =IF(A17="","",IF(H17="",AsOf-B17,H17-B17)) -> 24 | M17: =IF(A17="","",IF(AND(K17="Open",L17>Target),"Yes","No")) -> No | N17: =IF(K17<>"Open","",IF(L17<=30,"0-30",IF(L17<=60,"31-60",IF(L17<=90,"61-90","90+")))) | O17: =IF(A17="","",IF(COUNTIFS($D$5:$D$400,D17,$F$5:$F$400,F17,$B$5:$B$400,">="&(B17-RepeatWin),$B$5:$B$400,"<"&B17)>0,"Yes","No")) -> No | P17: =IF(OR(I17="",H17=""),"",H17+CapaDue) -> 45901 | Q17: =IF(A17="","",IF(I17="","Not required",IF(J17<>"","Closed",IF(H17="","Awaiting dev. close",IF(AsOf>P17,"Overdue","Open"))))) -> Closed | R17: =IF(J17="","",IF(COUNTIFS($D$5:$D$400,D17,$F$5:$F$400,F17,$B$5:$B$400,">"&J17,$B$5:$B$400,"<="&(J17+EffWin))>0,"Ineffective",IF(AsOf-J17>=EffWin,"Effective","Check pending"))) -> Effective | S17: =IF(A17="","",DATE(YEAR(B17),MONTH(B17),1)) -> 45778 | T17: =IF(H17="","",DATE(YEAR(H17),MONTH(H17),1)) -> 45809 | U17: =IF(H17="","",IF(AsOf-H17<=90,L17,"")) | V17: =IF(H17="","",IF(AND(AsOf-H17>90,AsOf-H17<=270),L17,""))
A18: DEV-25-0114 | B18: 45790 | C18: Valve assembly | D18: Tissue rinse station | E18: Minor | F18: GDP / documentation error | G18: S. Okafor | H18: 45808 | K18: =IF(A18="","",IF(H18="","Open","Closed")) -> Closed | L18: =IF(A18="","",IF(H18="",AsOf-B18,H18-B18)) -> 18 | M18: =IF(A18="","",IF(AND(K18="Open",L18>Target),"Yes","No")) -> No | N18: =IF(K18<>"Open","",IF(L18<=30,"0-30",IF(L18<=60,"31-60",IF(L18<=90,"61-90","90+")))) | O18: =IF(A18="","",IF(COUNTIFS($D$5:$D$400,D18,$F$5:$F$400,F18,$B$5:$B$400,">="&(B18-RepeatWin),$B$5:$B$400,"<"&B18)>0,"Yes","No")) -> No | P18: =IF(OR(I18="",H18=""),"",H18+CapaDue) | Q18: =IF(A18="","",IF(I18="","Not required",IF(J18<>"","Closed",IF(H18="","Awaiting dev. close",IF(AsOf>P18,"Overdue","Open"))))) -> Not required | R18: =IF(J18="","",IF(COUNTIFS($D$5:$D$400,D18,$F$5:$F$400,F18,$B$5:$B$400,">"&J18,$B$5:$B$400,"<="&(J18+EffWin))>0,"Ineffective",IF(AsOf-J18>=EffWin,"Effective","Check pending"))) | S18: =IF(A18="","",DATE(YEAR(B18),MONTH(B18),1)) -> 45778 | T18: =IF(H18="","",DATE(YEAR(H18),MONTH(H18),1)) -> 45778 | U18: =IF(H18="","",IF(AsOf-H18<=90,L18,"")) | V18: =IF(H18="","",IF(AND(AsOf-H18>90,AsOf-H18<=270),L18,""))
A19: DEV-25-0115 | B19: 45791 | C19: Valve assembly | D19: Holder assembly | E19: Minor | F19: GDP / documentation error | G19: J. Alvarez | H19: 45810 | K19: =IF(A19="","",IF(H19="","Open","Closed")) -> Closed | L19: =IF(A19="","",IF(H19="",AsOf-B19,H19-B19)) -> 19 | M19: =IF(A19="","",IF(AND(K19="Open",L19>Target),"Yes","No")) -> No | N19: =IF(K19<>"Open","",IF(L19<=30,"0-30",IF(L19<=60,"31-60",IF(L19<=90,"61-90","90+")))) | O19: =IF(A19="","",IF(COUNTIFS($D$5:$D$400,D19,$F$5:$F$400,F19,$B$5:$B$400,">="&(B19-RepeatWin),$B$5:$B$400,"<"&B19)>0,"Yes","No")) -> No | P19: =IF(OR(I19="",H19=""),"",H19+CapaDue) | Q19: =IF(A19="","",IF(I19="","Not required",IF(J19<>"","Closed",IF(H19="","Awaiting dev. close",IF(AsOf>P19,"Overdue","Open"))))) -> Not required | R19: =IF(J19="","",IF(COUNTIFS($D$5:$D$400,D19,$F$5:$F$400,F19,$B$5:$B$400,">"&J19,$B$5:$B$400,"<="&(J19+EffWin))>0,"Ineffective",IF(AsOf-J19>=EffWin,"Effective","Check pending"))) | S19: =IF(A19="","",DATE(YEAR(B19),MONTH(B19),1)) -> 45778 | T19: =IF(H19="","",DATE(YEAR(H19),MONTH(H19),1)) -> 45809 | U19: =IF(H19="","",IF(AsOf-H19<=90,L19,"")) | V19: =IF(H19="","",IF(AND(AsOf-H19>90,AsOf-H19<=270),L19,""))
A20: DEV-25-0116 | B20: 45791 | C20: Valve assembly | D20: Batch record review | E20: Minor | F20: Supplier material defect | G20: D. Kim | H20: 45808 | K20: =IF(A20="","",IF(H20="","Open","Closed")) -> Closed | L20: =IF(A20="","",IF(H20="",AsOf-B20,H20-B20)) -> 17 | M20: =IF(A20="","",IF(AND(K20="Open",L20>Target),"Yes","No")) -> No | N20: =IF(K20<>"Open","",IF(L20<=30,"0-30",IF(L20<=60,"31-60",IF(L20<=90,"61-90","90+")))) | O20: =IF(A20="","",IF(COUNTIFS($D$5:$D$400,D20,$F$5:$F$400,F20,$B$5:$B$400,">="&(B20-RepeatWin),$B$5:$B$400,"<"&B20)>0,"Yes","No")) -> No | P20: =IF(OR(I20="",H20=""),"",H20+CapaDue) | Q20: =IF(A20="","",IF(I20="","Not required",IF(J20<>"","Closed",IF(H20="","Awaiting dev. close",IF(AsOf>P20,"Overdue","Open"))))) -> Not required | R20: =IF(J20="","",IF(COUNTIFS($D$5:$D$400,D20,$F$5:$F$400,F20,$B$5:$B$400,">"&J20,$B$5:$B$400,"<="&(J20+EffWin))>0,"Ineffective",IF(AsOf-J20>=EffWin,"Effective","Check pending"))) | S20: =IF(A20="","",DATE(YEAR(B20),MONTH(B20),1)) -> 45778 | T20: =IF(H20="","",DATE(YEAR(H20),MONTH(H20),1)) -> 45778 | U20: =IF(H20="","",IF(AsOf-H20<=90,L20,"")) | V20: =IF(H20="","",IF(AND(AsOf-H20>90,AsOf-H20<=270),L20,""))
A21: DEV-25-0117 | B21: 45798 | C21: Valve assembly | D21: Batch record review | E21: Minor | F21: Equipment malfunction | G21: L. Haddad | H21: 45824 | K21: =IF(A21="","",IF(H21="","Open","Closed")) -> Closed | L21: =IF(A21="","",IF(H21="",AsOf-B21,H21-B21)) -> 26 | M21: =IF(A21="","",IF(AND(K21="Open",L21>Target),"Yes","No")) -> No | N21: =IF(K21<>"Open","",IF(L21<=30,"0-30",IF(L21<=60,"31-60",IF(L21<=90,"61-90","90+")))) | O21: =IF(A21="","",IF(COUNTIFS($D$5:$D$400,D21,$F$5:$F$400,F21,$B$5:$B$400,">="&(B21-RepeatWin),$B$5:$B$400,"<"&B21)>0,"Yes","No")) -> No | P21: =IF(OR(I21="",H21=""),"",H21+CapaDue) | Q21: =IF(A21="","",IF(I21="","Not required",IF(J21<>"","Closed",IF(H21="","Awaiting dev. close",IF(AsOf>P21,"Overdue","Open"))))) -> Not required | R21: =IF(J21="","",IF(COUNTIFS($D$5:$D$400,D21,$F$5:$F$400,F21,$B$5:$B$400,">"&J21,$B$5:$B$400,"<="&(J21+EffWin))>0,"Ineffective",IF(AsOf-J21>=EffWin,"Effective","Check pending"))) | S21: =IF(A21="","",DATE(YEAR(B21),MONTH(B21),1)) -> 45778 | T21: =IF(H21="","",DATE(YEAR(H21),MONTH(H21),1)) -> 45809 | U21: =IF(H21="","",IF(AsOf-H21<=90,L21,"")) | V21: =IF(H21="","",IF(AND(AsOf-H21>90,AsOf-H21<=270),L21,""))
A22: DEV-25-0118 | B22: 45804 | C22: Facilities | D22: Cleanroom HVAC AHU-3 | E22: Minor | F22: Environmental excursion | G22: S. Okafor | H22: 45816 | K22: =IF(A22="","",IF(H22="","Open","Closed")) -> Closed | L22: =IF(A22="","",IF(H22="",AsOf-B22,H22-B22)) -> 12 | M22: =IF(A22="","",IF(AND(K22="Open",L22>Target),"Yes","No")) -> No | N22: =IF(K22<>"Open","",IF(L22<=30,"0-30",IF(L22<=60,"31-60",IF(L22<=90,"61-90","90+")))) | O22: =IF(A22="","",IF(COUNTIFS($D$5:$D$400,D22,$F$5:$F$400,F22,$B$5:$B$400,">="&(B22-RepeatWin),$B$5:$B$400,"<"&B22)>0,"Yes","No")) -> No | P22: =IF(OR(I22="",H22=""),"",H22+CapaDue) | Q22: =IF(A22="","",IF(I22="","Not required",IF(J22<>"","Closed",IF(H22="","Awaiting dev. close",IF(AsOf>P22,"Overdue","Open"))))) -> Not required | R22: =IF(J22="","",IF(COUNTIFS($D$5:$D$400,D22,$F$5:$F$400,F22,$B$5:$B$400,">"&J22,$B$5:$B$400,"<="&(J22+EffWin))>0,"Ineffective",IF(AsOf-J22>=EffWin,"Effective","Check pending"))) | S22: =IF(A22="","",DATE(YEAR(B22),MONTH(B22),1)) -> 45778 | T22: =IF(H22="","",DATE(YEAR(H22),MONTH(H22),1)) -> 45809 | U22: =IF(H22="","",IF(AsOf-H22<=90,L22,"")) | V22: =IF(H22="","",IF(AND(AsOf-H22>90,AsOf-H22<=270),L22,""))
A23: DEV-25-0119 | B23: 45805 | C23: Valve assembly | D23: Batch record review | E23: Minor | F23: Procedure not followed | G23: K. Tran | H23: 45822 | K23: =IF(A23="","",IF(H23="","Open","Closed")) -> Closed | L23: =IF(A23="","",IF(H23="",AsOf-B23,H23-B23)) -> 17 | M23: =IF(A23="","",IF(AND(K23="Open",L23>Target),"Yes","No")) -> No | N23: =IF(K23<>"Open","",IF(L23<=30,"0-30",IF(L23<=60,"31-60",IF(L23<=90,"61-90","90+")))) | O23: =IF(A23="","",IF(COUNTIFS($D$5:$D$400,D23,$F$5:$F$400,F23,$B$5:$B$400,">="&(B23-RepeatWin),$B$5:$B$400,"<"&B23)>0,"Yes","No")) -> No | P23: =IF(OR(I23="",H23=""),"",H23+CapaDue) | Q23: =IF(A23="","",IF(I23="","Not required",IF(J23<>"","Closed",IF(H23="","Awaiting dev. close",IF(AsOf>P23,"Overdue","Open"))))) -> Not required | R23: =IF(J23="","",IF(COUNTIFS($D$5:$D$400,D23,$F$5:$F$400,F23,$B$5:$B$400,">"&J23,$B$5:$B$400,"<="&(J23+EffWin))>0,"Ineffective",IF(AsOf-J23>=EffWin,"Effective","Check pending"))) | S23: =IF(A23="","",DATE(YEAR(B23),MONTH(B23),1)) -> 45778 | T23: =IF(H23="","",DATE(YEAR(H23),MONTH(H23),1)) -> 45809 | U23: =IF(H23="","",IF(AsOf-H23<=90,L23,"")) | V23: =IF(H23="","",IF(AND(AsOf-H23>90,AsOf-H23<=270),L23,""))
A24: DEV-25-0120 | B24: 45810 | C24: Valve assembly | D24: Tissue rinse station | E24: Minor | F24: Equipment malfunction | G24: J. Alvarez | H24: 45822 | K24: =IF(A24="","",IF(H24="","Open","Closed")) -> Closed | L24: =IF(A24="","",IF(H24="",AsOf-B24,H24-B24)) -> 12 | M24: =IF(A24="","",IF(AND(K24="Open",L24>Target),"Yes","No")) -> No | N24: =IF(K24<>"Open","",IF(L24<=30,"0-30",IF(L24<=60,"31-60",IF(L24<=90,"61-90","90+")))) | O24: =IF(A24="","",IF(COUNTIFS($D$5:$D$400,D24,$F$5:$F$400,F24,$B$5:$B$400,">="&(B24-RepeatWin),$B$5:$B$400,"<"&B24)>0,"Yes","No")) -> No | P24: =IF(OR(I24="",H24=""),"",H24+CapaDue) | Q24: =IF(A24="","",IF(I24="","Not required",IF(J24<>"","Closed",IF(H24="","Awaiting dev. close",IF(AsOf>P24,"Overdue","Open"))))) -> Not required | R24: =IF(J24="","",IF(COUNTIFS($D$5:$D$400,D24,$F$5:$F$400,F24,$B$5:$B$400,">"&J24,$B$5:$B$400,"<="&(J24+EffWin))>0,"Ineffective",IF(AsOf-J24>=EffWin,"Effective","Check pending"))) | S24: =IF(A24="","",DATE(YEAR(B24),MONTH(B24),1)) -> 45809 | T24: =IF(H24="","",DATE(YEAR(H24),MONTH(H24),1)) -> 45809 | U24: =IF(H24="","",IF(AsOf-H24<=90,L24,"")) | V24: =IF(H24="","",IF(AND(AsOf-H24>90,AsOf-H24<=270),L24,""))
A25: DEV-25-0121 | B25: 45815 | C25: Packaging | D25: Packaging line PL-1 | E25: Minor | F25: GDP / documentation error | G25: D. Kim | H25: 45833 | K25: =IF(A25="","",IF(H25="","Open","Closed")) -> Closed | L25: =IF(A25="","",IF(H25="",AsOf-B25,H25-B25)) -> 18 | M25: =IF(A25="","",IF(AND(K25="Open",L25>Target),"Yes","No")) -> No | N25: =IF(K25<>"Open","",IF(L25<=30,"0-30",IF(L25<=60,"31-60",IF(L25<=90,"61-90","90+")))) | O25: =IF(A25="","",IF(COUNTIFS($D$5:$D$400,D25,$F$5:$F$400,F25,$B$5:$B$400,">="&(B25-RepeatWin),$B$5:$B$400,"<"&B25)>0,"Yes","No")) -> No | P25: =IF(OR(I25="",H25=""),"",H25+CapaDue) | Q25: =IF(A25="","",IF(I25="","Not required",IF(J25<>"","Closed",IF(H25="","Awaiting dev. close",IF(AsOf>P25,"Overdue","Open"))))) -> Not required | R25: =IF(J25="","",IF(COUNTIFS($D$5:$D$400,D25,$F$5:$F$400,F25,$B$5:$B$400,">"&J25,$B$5:$B$400,"<="&(J25+EffWin))>0,"Ineffective",IF(AsOf-J25>=EffWin,"Effective","Check pending"))) | S25: =IF(A25="","",DATE(YEAR(B25),MONTH(B25),1)) -> 45809 | T25: =IF(H25="","",DATE(YEAR(H25),MONTH(H25),1)) -> 45809 | U25: =IF(H25="","",IF(AsOf-H25<=90,L25,"")) | V25: =IF(H25="","",IF(AND(AsOf-H25>90,AsOf-H25<=270),L25,""))
A26: DEV-25-0122 | B26: 45818 | C26: Warehouse | D26: Quarantine cage | E26: Minor | F26: GDP / documentation error | G26: S. Okafor | H26: 45846 | K26: =IF(A26="","",IF(H26="","Open","Closed")) -> Closed | L26: =IF(A26="","",IF(H26="",AsOf-B26,H26-B26)) -> 28 | M26: =IF(A26="","",IF(AND(K26="Open",L26>Target),"Yes","No")) -> No | N26: =IF(K26<>"Open","",IF(L26<=30,"0-30",IF(L26<=60,"31-60",IF(L26<=90,"61-90","90+")))) | O26: =IF(A26="","",IF(COUNTIFS($D$5:$D$400,D26,$F$5:$F$400,F26,$B$5:$B$400,">="&(B26-RepeatWin),$B$5:$B$400,"<"&B26)>0,"Yes","No")) -> No | P26: =IF(OR(I26="",H26=""),"",H26+CapaDue) | Q26: =IF(A26="","",IF(I26="","Not required",IF(J26<>"","Closed",IF(H26="","Awaiting dev. close",IF(AsOf>P26,"Overdue","Open"))))) -> Not required | R26: =IF(J26="","",IF(COUNTIFS($D$5:$D$400,D26,$F$5:$F$400,F26,$B$5:$B$400,">"&J26,$B$5:$B$400,"<="&(J26+EffWin))>0,"Ineffective",IF(AsOf-J26>=EffWin,"Effective","Check pending"))) | S26: =IF(A26="","",DATE(YEAR(B26),MONTH(B26),1)) -> 45809 | T26: =IF(H26="","",DATE(YEAR(H26),MONTH(H26),1)) -> 45839 | U26: =IF(H26="","",IF(AsOf-H26<=90,L26,"")) | V26: =IF(H26="","",IF(AND(AsOf-H26>90,AsOf-H26<=270),L26,""))
A27: DEV-25-0123 | B27: 45823 | C27: Packaging | D27: Pouch sealer PS-2 | E27: Major | F27: Equipment malfunction | G27: S. Okafor | H27: 45848 | I27: CAPA-006 | J27: 45899 | K27: =IF(A27="","",IF(H27="","Open","Closed")) -> Closed | L27: =IF(A27="","",IF(H27="",AsOf-B27,H27-B27)) -> 25 | M27: =IF(A27="","",IF(AND(K27="Open",L27>Target),"Yes","No")) -> No | N27: =IF(K27<>"Open","",IF(L27<=30,"0-30",IF(L27<=60,"31-60",IF(L27<=90,"61-90","90+")))) | O27: =IF(A27="","",IF(COUNTIFS($D$5:$D$400,D27,$F$5:$F$400,F27,$B$5:$B$400,">="&(B27-RepeatWin),$B$5:$B$400,"<"&B27)>0,"Yes","No")) -> No | P27: =IF(OR(I27="",H27=""),"",H27+CapaDue) -> 45938 | Q27: =IF(A27="","",IF(I27="","Not required",IF(J27<>"","Closed",IF(H27="","Awaiting dev. close",IF(AsOf>P27,"Overdue","Open"))))) -> Closed | R27: =IF(J27="","",IF(COUNTIFS($D$5:$D$400,D27,$F$5:$F$400,F27,$B$5:$B$400,">"&J27,$B$5:$B$400,"<="&(J27+EffWin))>0,"Ineffective",IF(AsOf-J27>=EffWin,"Effective","Check pending"))) -> Effective | S27: =IF(A27="","",DATE(YEAR(B27),MONTH(B27),1)) -> 45809 | T27: =IF(H27="","",DATE(YEAR(H27),MONTH(H27),1)) -> 45839 | U27: =IF(H27="","",IF(AsOf-H27<=90,L27,"")) | V27: =IF(H27="","",IF(AND(AsOf-H27>90,AsOf-H27<=270),L27,""))
A28: DEV-25-0124 | B28: 45824 | C28: Sterilization | D28: Preconditioning room PC-1 | E28: Minor | F28: Calibration overdue | G28: K. Tran | H28: 45844 | K28: =IF(A28="","",IF(H28="","Open","Closed")) -> Closed | L28: =IF(A28="","",IF(H28="",AsOf-B28,H28-B28)) -> 20 | M28: =IF(A28="","",IF(AND(K28="Open",L28>Target),"Yes","No")) -> No | N28: =IF(K28<>"Open","",IF(L28<=30,"0-30",IF(L28<=60,"31-60",IF(L28<=90,"61-90","90+")))) | O28: =IF(A28="","",IF(COUNTIFS($D$5:$D$400,D28,$F$5:$F$400,F28,$B$5:$B$400,">="&(B28-RepeatWin),$B$5:$B$400,"<"&B28)>0,"Yes","No")) -> No | P28: =IF(OR(I28="",H28=""),"",H28+CapaDue) | Q28: =IF(A28="","",IF(I28="","Not required",IF(J28<>"","Closed",IF(H28="","Awaiting dev. close",IF(AsOf>P28,"Overdue","Open"))))) -> Not required | R28: =IF(J28="","",IF(COUNTIFS($D$5:$D$400,D28,$F$5:$F$400,F28,$B$5:$B$400,">"&J28,$B$5:$B$400,"<="&(J28+EffWin))>0,"Ineffective",IF(AsOf-J28>=EffWin,"Effective","Check pending"))) | S28: =IF(A28="","",DATE(YEAR(B28),MONTH(B28),1)) -> 45809 | T28: =IF(H28="","",DATE(YEAR(H28),MONTH(H28),1)) -> 45839 | U28: =IF(H28="","",IF(AsOf-H28<=90,L28,"")) | V28: =IF(H28="","",IF(AND(AsOf-H28>90,AsOf-H28<=270),L28,""))
A29: DEV-25-0125 | B29: 45829 | C29: Warehouse | D29: Raw material sampling | E29: Minor | F29: Temperature excursion | G29: M. Chen | H29: 45854 | K29: =IF(A29="","",IF(H29="","Open","Closed")) -> Closed | L29: =IF(A29="","",IF(H29="",AsOf-B29,H29-B29)) -> 25 | M29: =IF(A29="","",IF(AND(K29="Open",L29>Target),"Yes","No")) -> No | N29: =IF(K29<>"Open","",IF(L29<=30,"0-30",IF(L29<=60,"31-60",IF(L29<=90,"61-90","90+")))) | O29: =IF(A29="","",IF(COUNTIFS($D$5:$D$400,D29,$F$5:$F$400,F29,$B$5:$B$400,">="&(B29-RepeatWin),$B$5:$B$400,"<"&B29)>0,"Yes","No")) -> No | P29: =IF(OR(I29="",H29=""),"",H29+CapaDue) | Q29: =IF(A29="","",IF(I29="","Not required",IF(J29<>"","Closed",IF(H29="","Awaiting dev. close",IF(AsOf>P29,"Overdue","Open"))))) -> Not required | R29: =IF(J29="","",IF(COUNTIFS($D$5:$D$400,D29,$F$5:$F$400,F29,$B$5:$B$400,">"&J29,$B$5:$B$400,"<="&(J29+EffWin))>0,"Ineffective",IF(AsOf-J29>=EffWin,"Effective","Check pending"))) | S29: =IF(A29="","",DATE(YEAR(B29),MONTH(B29),1)) -> 45809 | T29: =IF(H29="","",DATE(YEAR(H29),MONTH(H29),1)) -> 45839 | U29: =IF(H29="","",IF(AsOf-H29<=90,L29,"")) | V29: =IF(H29="","",IF(AND(AsOf-H29>90,AsOf-H29<=270),L29,""))
A30: DEV-25-0126 | B30: 45834 | C30: Warehouse | D30: Cold storage CS-1 | E30: Minor | F30: Temperature excursion | G30: M. Chen | H30: 45856 | K30: =IF(A30="","",IF(H30="","Open","Closed")) -> Closed | L30: =IF(A30="","",IF(H30="",AsOf-B30,H30-B30)) -> 22 | M30: =IF(A30="","",IF(AND(K30="Open",L30>Target),"Yes","No")) -> No | N30: =IF(K30<>"Open","",IF(L30<=30,"0-30",IF(L30<=60,"31-60",IF(L30<=90,"61-90","90+")))) | O30: =IF(A30="","",IF(COUNTIFS($D$5:$D$400,D30,$F$5:$F$400,F30,$B$5:$B$400,">="&(B30-RepeatWin),$B$5:$B$400,"<"&B30)>0,"Yes","No")) -> No | P30: =IF(OR(I30="",H30=""),"",H30+CapaDue) | Q30: =IF(A30="","",IF(I30="","Not required",IF(J30<>"","Closed",IF(H30="","Awaiting dev. close",IF(AsOf>P30,"Overdue","Open"))))) -> Not required | R30: =IF(J30="","",IF(COUNTIFS($D$5:$D$400,D30,$F$5:$F$400,F30,$B$5:$B$400,">"&J30,$B$5:$B$400,"<="&(J30+EffWin))>0,"Ineffective",IF(AsOf-J30>=EffWin,"Effective","Check pending"))) | S30: =IF(A30="","",DATE(YEAR(B30),MONTH(B30),1)) -> 45809 | T30: =IF(H30="","",DATE(YEAR(H30),MONTH(H30),1)) -> 45839 | U30: =IF(H30="","",IF(AsOf-H30<=90,L30,"")) | V30: =IF(H30="","",IF(AND(AsOf-H30>90,AsOf-H30<=270),L30,""))
A31: DEV-25-0127 | B31: 45834 | C31: Warehouse | D31: Finished goods dispatch | E31: Minor | F31: Supplier material defect | G31: S. Okafor | H31: 45848 | K31: =IF(A31="","",IF(H31="","Open","Closed")) -> Closed | L31: =IF(A31="","",IF(H31="",AsOf-B31,H31-B31)) -> 14 | M31: =IF(A31="","",IF(AND(K31="Open",L31>Target),"Yes","No")) -> No | N31: =IF(K31<>"Open","",IF(L31<=30,"0-30",IF(L31<=60,"31-60",IF(L31<=90,"61-90","90+")))) | O31: =IF(A31="","",IF(COUNTIFS($D$5:$D$400,D31,$F$5:$F$400,F31,$B$5:$B$400,">="&(B31-RepeatWin),$B$5:$B$400,"<"&B31)>0,"Yes","No")) -> No | P31: =IF(OR(I31="",H31=""),"",H31+CapaDue) | Q31: =IF(A31="","",IF(I31="","Not required",IF(J31<>"","Closed",IF(H31="","Awaiting dev. close",IF(AsOf>P31,"Overdue","Open"))))) -> Not required | R31: =IF(J31="","",IF(COUNTIFS($D$5:$D$400,D31,$F$5:$F$400,F31,$B$5:$B$400,">"&J31,$B$5:$B$400,"<="&(J31+EffWin))>0,"Ineffective",IF(AsOf-J31>=EffWin,"Effective","Check pending"))) | S31: =IF(A31="","",DATE(YEAR(B31),MONTH(B31),1)) -> 45809 | T31: =IF(H31="","",DATE(YEAR(H31),MONTH(H31),1)) -> 45839 | U31: =IF(H31="","",IF(AsOf-H31<=90,L31,"")) | V31: =IF(H31="","",IF(AND(AsOf-H31>90,AsOf-H31<=270),L31,""))
A32: DEV-25-0128 | B32: 45835 | C32: Valve assembly | D32: Batch record review | E32: Minor | F32: GDP / documentation error | G32: D. Kim | H32: 45853 | K32: =IF(A32="","",IF(H32="","Open","Closed")) -> Closed | L32: =IF(A32="","",IF(H32="",AsOf-B32,H32-B32)) -> 18 | M32: =IF(A32="","",IF(AND(K32="Open",L32>Target),"Yes","No")) -> No | N32: =IF(K32<>"Open","",IF(L32<=30,"0-30",IF(L32<=60,"31-60",IF(L32<=90,"61-90","90+")))) | O32: =IF(A32="","",IF(COUNTIFS($D$5:$D$400,D32,$F$5:$F$400,F32,$B$5:$B$400,">="&(B32-RepeatWin),$B$5:$B$400,"<"&B32)>0,"Yes","No")) -> No | P32: =IF(OR(I32="",H32=""),"",H32+CapaDue) | Q32: =IF(A32="","",IF(I32="","Not required",IF(J32<>"","Closed",IF(H32="","Awaiting dev. close",IF(AsOf>P32,"Overdue","Open"))))) -> Not required | R32: =IF(J32="","",IF(COUNTIFS($D$5:$D$400,D32,$F$5:$F$400,F32,$B$5:$B$400,">"&J32,$B$5:$B$400,"<="&(J32+EffWin))>0,"Ineffective",IF(AsOf-J32>=EffWin,"Effective","Check pending"))) | S32: =IF(A32="","",DATE(YEAR(B32),MONTH(B32),1)) -> 45809 | T32: =IF(H32="","",DATE(YEAR(H32),MONTH(H32),1)) -> 45839 | U32: =IF(H32="","",IF(AsOf-H32<=90,L32,"")) | V32: =IF(H32="","",IF(AND(AsOf-H32>90,AsOf-H32<=270),L32,""))
A33: DEV-25-0129 | B33: 45837 | C33: QC Microbiology | D33: Endotoxin (LAL) testing | E33: Minor | F33: GDP / documentation error | G33: M. Chen | H33: 45856 | K33: =IF(A33="","",IF(H33="","Open","Closed")) -> Closed | L33: =IF(A33="","",IF(H33="",AsOf-B33,H33-B33)) -> 19 | M33: =IF(A33="","",IF(AND(K33="Open",L33>Target),"Yes","No")) -> No | N33: =IF(K33<>"Open","",IF(L33<=30,"0-30",IF(L33<=60,"31-60",IF(L33<=90,"61-90","90+")))) | O33: =IF(A33="","",IF(COUNTIFS($D$5:$D$400,D33,$F$5:$F$400,F33,$B$5:$B$400,">="&(B33-RepeatWin),$B$5:$B$400,"<"&B33)>0,"Yes","No")) -> No | P33: =IF(OR(I33="",H33=""),"",H33+CapaDue) | Q33: =IF(A33="","",IF(I33="","Not required",IF(J33<>"","Closed",IF(H33="","Awaiting dev. close",IF(AsOf>P33,"Overdue","Open"))))) -> Not required | R33: =IF(J33="","",IF(COUNTIFS($D$5:$D$400,D33,$F$5:$F$400,F33,$B$5:$B$400,">"&J33,$B$5:$B$400,"<="&(J33+EffWin))>0,"Ineffective",IF(AsOf-J33>=EffWin,"Effective","Check pending"))) | S33: =IF(A33="","",DATE(YEAR(B33),MONTH(B33),1)) -> 45809 | T33: =IF(H33="","",DATE(YEAR(H33),MONTH(H33),1)) -> 45839 | U33: =IF(H33="","",IF(AsOf-H33<=90,L33,"")) | V33: =IF(H33="","",IF(AND(AsOf-H33>90,AsOf-H33<=270),L33,""))
A34: DEV-25-0130 | B34: 45840 | C34: Valve assembly | D34: Frame crimping station | E34: Critical | F34: GDP / documentation error | G34: M. Chen | H34: 45867 | I34: CAPA-007 | J34: 45936 | K34: =IF(A34="","",IF(H34="","Open","Closed")) -> Closed | L34: =IF(A34="","",IF(H34="",AsOf-B34,H34-B34)) -> 27 | M34: =IF(A34="","",IF(AND(K34="Open",L34>Target),"Yes","No")) -> No | N34: =IF(K34<>"Open","",IF(L34<=30,"0-30",IF(L34<=60,"31-60",IF(L34<=90,"61-90","90+")))) | O34: =IF(A34="","",IF(COUNTIFS($D$5:$D$400,D34,$F$5:$F$400,F34,$B$5:$B$400,">="&(B34-RepeatWin),$B$5:$B$400,"<"&B34)>0,"Yes","No")) -> No | P34: =IF(OR(I34="",H34=""),"",H34+CapaDue) -> 45957 | Q34: =IF(A34="","",IF(I34="","Not required",IF(J34<>"","Closed",IF(H34="","Awaiting dev. close",IF(AsOf>P34,"Overdue","Open"))))) -> Closed | R34: =IF(J34="","",IF(COUNTIFS($D$5:$D$400,D34,$F$5:$F$400,F34,$B$5:$B$400,">"&J34,$B$5:$B$400,"<="&(J34+EffWin))>0,"Ineffective",IF(AsOf-J34>=EffWin,"Effective","Check pending"))) -> Effective | S34: =IF(A34="","",DATE(YEAR(B34),MONTH(B34),1)) -> 45839 | T34: =IF(H34="","",DATE(YEAR(H34),MONTH(H34),1)) -> 45839 | U34: =IF(H34="","",IF(AsOf-H34<=90,L34,"")) | V34: =IF(H34="","",IF(AND(AsOf-H34>90,AsOf-H34<=270),L34,""))
A35: DEV-25-0131 | B35: 45844 | C35: Packaging | D35: Label printer LP-3 | E35: Minor | F35: Equipment malfunction | G35: K. Tran | H35: 45859 | K35: =IF(A35="","",IF(H35="","Open","Closed")) -> Closed | L35: =IF(A35="","",IF(H35="",AsOf-B35,H35-B35)) -> 15 | M35: =IF(A35="","",IF(AND(K35="Open",L35>Target),"Yes","No")) -> No | N35: =IF(K35<>"Open","",IF(L35<=30,"0-30",IF(L35<=60,"31-60",IF(L35<=90,"61-90","90+")))) | O35: =IF(A35="","",IF(COUNTIFS($D$5:$D$400,D35,$F$5:$F$400,F35,$B$5:$B$400,">="&(B35-RepeatWin),$B$5:$B$400,"<"&B35)>0,"Yes","No")) -> No | P35: =IF(OR(I35="",H35=""),"",H35+CapaDue) | Q35: =IF(A35="","",IF(I35="","Not required",IF(J35<>"","Closed",IF(H35="","Awaiting dev. close",IF(AsOf>P35,"Overdue","Open"))))) -> Not required | R35: =IF(J35="","",IF(COUNTIFS($D$5:$D$400,D35,$F$5:$F$400,F35,$B$5:$B$400,">"&J35,$B$5:$B$400,"<="&(J35+EffWin))>0,"Ineffective",IF(AsOf-J35>=EffWin,"Effective","Check pending"))) | S35: =IF(A35="","",DATE(YEAR(B35),MONTH(B35),1)) -> 45839 | T35: =IF(H35="","",DATE(YEAR(H35),MONTH(H35),1)) -> 45839 | U35: =IF(H35="","",IF(AsOf-H35<=90,L35,"")) | V35: =IF(H35="","",IF(AND(AsOf-H35>90,AsOf-H35<=270),L35,""))
A36: DEV-25-0132 | B36: 45846 | C36: Valve assembly | D36: Batch record review | E36: Minor | F36: Training gap | G36: R. Patel | H36: 45860 | K36: =IF(A36="","",IF(H36="","Open","Closed")) -> Closed | L36: =IF(A36="","",IF(H36="",AsOf-B36,H36-B36)) -> 14 | M36: =IF(A36="","",IF(AND(K36="Open",L36>Target),"Yes","No")) -> No | N36: =IF(K36<>"Open","",IF(L36<=30,"0-30",IF(L36<=60,"31-60",IF(L36<=90,"61-90","90+")))) | O36: =IF(A36="","",IF(COUNTIFS($D$5:$D$400,D36,$F$5:$F$400,F36,$B$5:$B$400,">="&(B36-RepeatWin),$B$5:$B$400,"<"&B36)>0,"Yes","No")) -> No | P36: =IF(OR(I36="",H36=""),"",H36+CapaDue) | Q36: =IF(A36="","",IF(I36="","Not required",IF(J36<>"","Closed",IF(H36="","Awaiting dev. close",IF(AsOf>P36,"Overdue","Open"))))) -> Not required | R36: =IF(J36="","",IF(COUNTIFS($D$5:$D$400,D36,$F$5:$F$400,F36,$B$5:$B$400,">"&J36,$B$5:$B$400,"<="&(J36+EffWin))>0,"Ineffective",IF(AsOf-J36>=EffWin,"Effective","Check pending"))) | S36: =IF(A36="","",DATE(YEAR(B36),MONTH(B36),1)) -> 45839 | T36: =IF(H36="","",DATE(YEAR(H36),MONTH(H36),1)) -> 45839 | U36: =IF(H36="","",IF(AsOf-H36<=90,L36,"")) | V36: =IF(H36="","",IF(AND(AsOf-H36>90,AsOf-H36<=270),L36,""))
A37: DEV-25-0133 | B37: 45847 | C37: Facilities | D37: Gowning room GR-2 | E37: Critical | F37: Preventive maintenance missed | G37: M. Chen | H37: 45867 | I37: CAPA-008 | J37: 45933 | K37: =IF(A37="","",IF(H37="","Open","Closed")) -> Closed | L37: =IF(A37="","",IF(H37="",AsOf-B37,H37-B37)) -> 20 | M37: =IF(A37="","",IF(AND(K37="Open",L37>Target),"Yes","No")) -> No | N37: =IF(K37<>"Open","",IF(L37<=30,"0-30",IF(L37<=60,"31-60",IF(L37<=90,"61-90","90+")))) | O37: =IF(A37="","",IF(COUNTIFS($D$5:$D$400,D37,$F$5:$F$400,F37,$B$5:$B$400,">="&(B37-RepeatWin),$B$5:$B$400,"<"&B37)>0,"Yes","No")) -> No | P37: =IF(OR(I37="",H37=""),"",H37+CapaDue) -> 45957 | Q37: =IF(A37="","",IF(I37="","Not required",IF(J37<>"","Closed",IF(H37="","Awaiting dev. close",IF(AsOf>P37,"Overdue","Open"))))) -> Closed | R37: =IF(J37="","",IF(COUNTIFS($D$5:$D$400,D37,$F$5:$F$400,F37,$B$5:$B$400,">"&J37,$B$5:$B$400,"<="&(J37+EffWin))>0,"Ineffective",IF(AsOf-J37>=EffWin,"Effective","Check pending"))) -> Effective | S37: =IF(A37="","",DATE(YEAR(B37),MONTH(B37),1)) -> 45839 | T37: =IF(H37="","",DATE(YEAR(H37),MONTH(H37),1)) -> 45839 | U37: =IF(H37="","",IF(AsOf-H37<=90,L37,"")) | V37: =IF(H37="","",IF(AND(AsOf-H37>90,AsOf-H37<=270),L37,""))
A38: DEV-25-0134 | B38: 45850 | C38: QC Microbiology | D38: Endotoxin (LAL) testing | E38: Minor | F38: Procedure not followed | G38: S. Okafor | H38: 45861 | K38: =IF(A38="","",IF(H38="","Open","Closed")) -> Closed | L38: =IF(A38="","",IF(H38="",AsOf-B38,H38-B38)) -> 11 | M38: =IF(A38="","",IF(AND(K38="Open",L38>Target),"Yes","No")) -> No | N38: =IF(K38<>"Open","",IF(L38<=30,"0-30",IF(L38<=60,"31-60",IF(L38<=90,"61-90","90+")))) | O38: =IF(A38="","",IF(COUNTIFS($D$5:$D$400,D38,$F$5:$F$400,F38,$B$5:$B$400,">="&(B38-RepeatWin),$B$5:$B$400,"<"&B38)>0,"Yes","No")) -> No | P38: =IF(OR(I38="",H38=""),"",H38+CapaDue) | Q38: =IF(A38="","",IF(I38="","Not required",IF(J38<>"","Closed",IF(H38="","Awaiting dev. close",IF(AsOf>P38,"Overdue","Open"))))) -> Not required | R38: =IF(J38="","",IF(COUNTIFS($D$5:$D$400,D38,$F$5:$F$400,F38,$B$5:$B$400,">"&J38,$B$5:$B$400,"<="&(J38+EffWin))>0,"Ineffective",IF(AsOf-J38>=EffWin,"Effective","Check pending"))) | S38: =IF(A38="","",DATE(YEAR(B38),MONTH(B38),1)) -> 45839 | T38: =IF(H38="","",DATE(YEAR(H38),MONTH(H38),1)) -> 45839 | U38: =IF(H38="","",IF(AsOf-H38<=90,L38,"")) | V38: =IF(H38="","",IF(AND(AsOf-H38>90,AsOf-H38<=270),L38,""))
A39: DEV-25-0135 | B39: 45851 | C39: QC Microbiology | D39: Bioburden testing | E39: Minor | F39: Sample handling error | G39: D. Kim | H39: 45866 | K39: =IF(A39="","",IF(H39="","Open","Closed")) -> Closed | L39: =IF(A39="","",IF(H39="",AsOf-B39,H39-B39)) -> 15 | M39: =IF(A39="","",IF(AND(K39="Open",L39>Target),"Yes","No")) -> No | N39: =IF(K39<>"Open","",IF(L39<=30,"0-30",IF(L39<=60,"31-60",IF(L39<=90,"61-90","90+")))) | O39: =IF(A39="","",IF(COUNTIFS($D$5:$D$400,D39,$F$5:$F$400,F39,$B$5:$B$400,">="&(B39-RepeatWin),$B$5:$B$400,"<"&B39)>0,"Yes","No")) -> No | P39: =IF(OR(I39="",H39=""),"",H39+CapaDue) | Q39: =IF(A39="","",IF(I39="","Not required",IF(J39<>"","Closed",IF(H39="","Awaiting dev. close",IF(AsOf>P39,"Overdue","Open"))))) -> Not required | R39: =IF(J39="","",IF(COUNTIFS($D$5:$D$400,D39,$F$5:$F$400,F39,$B$5:$B$400,">"&J39,$B$5:$B$400,"<="&(J39+EffWin))>0,"Ineffective",IF(AsOf-J39>=EffWin,"Effective","Check pending"))) | S39: =IF(A39="","",DATE(YEAR(B39),MONTH(B39),1)) -> 45839 | T39: =IF(H39="","",DATE(YEAR(H39),MONTH(H39),1)) -> 45839 | U39: =IF(H39="","",IF(AsOf-H39<=90,L39,"")) | V39: =IF(H39="","",IF(AND(AsOf-H39>90,AsOf-H39<=270),L39,""))
A40: DEV-25-0136 | B40: 45858 | C40: QC Microbiology | D40: Sterility testing | E40: Major | F40: GDP / documentation error | G40: J. Alvarez | H40: 45893 | I40: CAPA-009 | J40: 45962 | K40: =IF(A40="","",IF(H40="","Open","Closed")) -> Closed | L40: =IF(A40="","",IF(H40="",AsOf-B40,H40-B40)) -> 35 | M40: =IF(A40="","",IF(AND(K40="Open",L40>Target),"Yes","No")) -> No | N40: =IF(K40<>"Open","",IF(L40<=30,"0-30",IF(L40<=60,"31-60",IF(L40<=90,"61-90","90+")))) | O40: =IF(A40="","",IF(COUNTIFS($D$5:$D$400,D40,$F$5:$F$400,F40,$B$5:$B$400,">="&(B40-RepeatWin),$B$5:$B$400,"<"&B40)>0,"Yes","No")) -> No | P40: =IF(OR(I40="",H40=""),"",H40+CapaDue) -> 45983 | Q40: =IF(A40="","",IF(I40="","Not required",IF(J40<>"","Closed",IF(H40="","Awaiting dev. close",IF(AsOf>P40,"Overdue","Open"))))) -> Closed | R40: =IF(J40="","",IF(COUNTIFS($D$5:$D$400,D40,$F$5:$F$400,F40,$B$5:$B$400,">"&J40,$B$5:$B$400,"<="&(J40+EffWin))>0,"Ineffective",IF(AsOf-J40>=EffWin,"Effective","Check pending"))) -> Effective | S40: =IF(A40="","",DATE(YEAR(B40),MONTH(B40),1)) -> 45839 | T40: =IF(H40="","",DATE(YEAR(H40),MONTH(H40),1)) -> 45870 | U40: =IF(H40="","",IF(AsOf-H40<=90,L40,"")) | V40: =IF(H40="","",IF(AND(AsOf-H40>90,AsOf-H40<=270),L40,""))
